Failure # 1 (occurred at 2021-09-08_10-30-08)
Traceback (most recent call last):
  File "/home/phesse/.local/lib/python3.8/site-packages/ray/tune/trial_runner.py", line 718, in _process_trial
    results = self.trial_executor.fetch_result(trial)
  File "/home/phesse/.local/lib/python3.8/site-packages/ray/tune/ray_trial_executor.py", line 688, in fetch_result
    result = ray.get(trial_future[0], timeout=DEFAULT_GET_TIMEOUT)
  File "/home/phesse/.local/lib/python3.8/site-packages/ray/_private/client_mode_hook.py", line 62, in wrapper
    return func(*args, **kwargs)
  File "/home/phesse/.local/lib/python3.8/site-packages/ray/worker.py", line 1495, in get
    raise value.as_instanceof_cause()
ray.exceptions.RayTaskError(TypeError): [36mray::PPO.train_buffered()[39m (pid=4409, ip=152.65.229.168)
  File "python/ray/_raylet.pyx", line 501, in ray._raylet.execute_task
  File "python/ray/_raylet.pyx", line 451, in ray._raylet.execute_task.function_executor
  File "/home/phesse/.local/lib/python3.8/site-packages/ray/_private/function_manager.py", line 563, in actor_method_executor
    return method(__ray_actor, *args, **kwargs)
  File "/home/phesse/.local/lib/python3.8/site-packages/ray/tune/trainable.py", line 173, in train_buffered
    result = self.train()
  File "/home/phesse/.local/lib/python3.8/site-packages/ray/rllib/agents/trainer.py", line 605, in train
    raise e
  File "/home/phesse/.local/lib/python3.8/site-packages/ray/rllib/agents/trainer.py", line 594, in train
    result = Trainable.train(self)
  File "/home/phesse/.local/lib/python3.8/site-packages/ray/tune/trainable.py", line 232, in train
    result = self.step()
  File "/home/phesse/.local/lib/python3.8/site-packages/ray/rllib/agents/trainer_template.py", line 173, in step
    res = next(self.train_exec_impl)
  File "/home/phesse/.local/lib/python3.8/site-packages/ray/util/iter.py", line 756, in __next__
    return next(self.built_iterator)
  File "/home/phesse/.local/lib/python3.8/site-packages/ray/util/iter.py", line 783, in apply_foreach
    for item in it:
  File "/home/phesse/.local/lib/python3.8/site-packages/ray/util/iter.py", line 783, in apply_foreach
    for item in it:
  File "/home/phesse/.local/lib/python3.8/site-packages/ray/util/iter.py", line 843, in apply_filter
    for item in it:
  File "/home/phesse/.local/lib/python3.8/site-packages/ray/util/iter.py", line 843, in apply_filter
    for item in it:
  File "/home/phesse/.local/lib/python3.8/site-packages/ray/util/iter.py", line 783, in apply_foreach
    for item in it:
  File "/home/phesse/.local/lib/python3.8/site-packages/ray/util/iter.py", line 783, in apply_foreach
    for item in it:
  File "/home/phesse/.local/lib/python3.8/site-packages/ray/util/iter.py", line 783, in apply_foreach
    for item in it:
  [Previous line repeated 1 more time]
  File "/home/phesse/.local/lib/python3.8/site-packages/ray/util/iter.py", line 876, in apply_flatten
    for item in it:
  File "/home/phesse/.local/lib/python3.8/site-packages/ray/util/iter.py", line 828, in add_wait_hooks
    item = next(it)
  File "/home/phesse/.local/lib/python3.8/site-packages/ray/util/iter.py", line 783, in apply_foreach
    for item in it:
  File "/home/phesse/.local/lib/python3.8/site-packages/ray/util/iter.py", line 783, in apply_foreach
    for item in it:
  File "/home/phesse/.local/lib/python3.8/site-packages/ray/util/iter.py", line 783, in apply_foreach
    for item in it:
  [Previous line repeated 1 more time]
  File "/home/phesse/.local/lib/python3.8/site-packages/ray/util/iter.py", line 471, in base_iterator
    yield ray.get(futures, timeout=timeout)
  File "/home/phesse/.local/lib/python3.8/site-packages/ray/_private/client_mode_hook.py", line 62, in wrapper
    return func(*args, **kwargs)
ray.exceptions.RayTaskError(TypeError): [36mray::RolloutWorker.par_iter_next()[39m (pid=4402, ip=152.65.229.168)
  File "python/ray/_raylet.pyx", line 501, in ray._raylet.execute_task
  File "python/ray/_raylet.pyx", line 451, in ray._raylet.execute_task.function_executor
  File "/home/phesse/.local/lib/python3.8/site-packages/ray/_private/function_manager.py", line 563, in actor_method_executor
    return method(__ray_actor, *args, **kwargs)
  File "/home/phesse/.local/lib/python3.8/site-packages/ray/util/iter.py", line 1151, in par_iter_next
    return next(self.local_it)
  File "/home/phesse/.local/lib/python3.8/site-packages/ray/rllib/evaluation/rollout_worker.py", line 333, in gen_rollouts
    yield self.sample()
  File "/home/phesse/.local/lib/python3.8/site-packages/ray/rllib/evaluation/rollout_worker.py", line 726, in sample
    batches = [self.input_reader.next()]
  File "/home/phesse/.local/lib/python3.8/site-packages/ray/rllib/evaluation/sampler.py", line 99, in next
    batches = [self.get_data()]
  File "/home/phesse/.local/lib/python3.8/site-packages/ray/rllib/evaluation/sampler.py", line 226, in get_data
    item = next(self.rollout_provider)
  File "/home/phesse/.local/lib/python3.8/site-packages/ray/rllib/evaluation/sampler.py", line 651, in _env_runner
    base_env.send_actions(actions_to_send)
  File "/home/phesse/.local/lib/python3.8/site-packages/ray/rllib/env/base_env.py", line 363, in send_actions
    self.vector_env.vector_step(action_vector)
  File "/home/phesse/.local/lib/python3.8/site-packages/ray/rllib/env/vector_env.py", line 167, in vector_step
    obs, r, done, info = self.envs[i].step(actions[i])
  File "/home/phesse/.local/lib/python3.8/site-packages/compiler_gym/wrappers/core.py", line 42, in step
    return self.env.step(action, observations=observations, rewards=rewards)
TypeError: step() got an unexpected keyword argument 'observations'

